<!DOCTYPE html>
<html lang="en">
  <head>
    <meta charset="UTF-8" />
    <meta name="viewport" content="width=device-width, initial-scale=1.0" />
    <title>Document</title>
  </head>
  <body>
    <script>
      // 重写原本方法
      // 证明catch 是 Promise.prototype.then(undefined,onRejected)的简写
      //    ((Promise)=>{
      //     const originalThen = Promise.prototype.then
      //     const originalCatch = Promise.prototype.catch
      //     Promise.prototype.then = function(...args){
      //         console.log('调用then方法',this,args);
      //         return originalThen.apply(this,args)
      //     }
      //     Promise.prototype.catch = function(...args){
      //         console.log('调用catch方法',this,args);
      //         return originalCatch.apply(this,args)
      //     }
      //    })(Promise)
      //    Promise.resolve().catch((err)=>{console.log(err)})

      // const p1 = Promise.resolve('成功')
      // p1.then(val=>{throw new Error('失败')})
      // .catch(e=>{console.log(e)})
      // .then(res=>console.log(res,'1'),err=>console.log(err))
      // error  undefined 1

      // const p1 = new Promise((resolve, reject) => {
      // throw new Error("哦吼！");
      // });

      // p1.catch((e) => {
      // console.error(e); // "哦吼！"
      // });

      //   在异步函数内部抛出的错误会像未捕获的错误一样：
      //   const p2 = new Promise((resolve, reject) => {
      //     setTimeout(() => {
      //       throw new Error("未捕获的异常！");
      //     }, 1000);
      //   });

      //   p2.catch((e) => {
      //     console.error(e); // 永远不会被调用
      //   });

      //   const p3 = new Promise((resolve, reject) => {
      //     resolve();
      //     throw new Error("Silenced Exception!");
      //   });

      //   p3.catch((e) => {
      //     console.error(e); // 这里永远不会执行
      //   });

      // 如果 Promise 已兑现，catch() 不会被调用
      // 创建一个不会调用 onReject 的 Promise
      const p1 = Promise.resolve("调用下一个");
      const p2 = p1.catch((reason) => {
        // 这里永远不会执行   p2 => p1
        console.error("p1 的 catch 函数被调用了！");
        console.error(reason);
      });
      p2.then(
        (value) => {
          console.log("下一个 Promise 的 onFulfilled 函数被调用了");
          console.log(value); // 调用下一个
        },
        (reason) => {
          console.log("下一个 Promise 的 onRejected 函数被调用了");
          console.log(reason);
        }
      );
    </script>
  </body>
</html>
