<!DOCTYPE html>
<html lang="en">
<head>
    <meta charset="UTF-8">
    <meta name="viewport" content="width=device-width, initial-scale=1.0">
    <title>Document</title>
</head>
<body>
    <script>
        // 普通使用
        // const p1  = new Promise((resolve,reject)=>{
        //     // resolve('成功')
        //     reject('错误')
        // })
        // p1.then(res=>console.log(res)).catch(err=>console.log(err))

        // 传入非函数

        // console.log(    Promise.resolve(1));   //Promise{<fullfilled>:1}
        // console.log( Promise.resolve(1).then(2) );  // pending
        // Promise.resolve(1).then(2).then(res=>console.log(res)) //1  恒等值 被认为是(val)=>val 2不会起作用
        // Promise.reject(2).then(3,3).then(res=>console.log(res),err=>console.log(err))
        // Promise.resolve(2).then((val)=>val+1).then(res=>console.log(res),err=>console.log(err)) //函数返回一个新的promise

        // then() 方法返回的值的解决方式与 Promise.resolve() 相同
        // const p2 = new Promise((resolve, reject) => { resolve(1); });
        // p2.then((val)=>val+1).then(val=>console.log(val)) //2
        // p2.then(val=>console.log(val)) //1

        // 如果函数抛出错误或返回一个被拒绝的 Promise，则 then 返回的 Promise 最终将被拒绝  then第二个参数处理异常后，catch不会再执行
        // Promise.resolve().then(res=>{throw new Error('Oh no!')}).then(res=>console.log(res),err=>console.log(err)).catch(err=>console.log(err,111))
            

        // 其他所有情况下，返回的 Promise 最终都会被兑现。
        // 在下面的示例中，即使链中的前一个 Promise 被拒绝，第一个 then() 返回一个包装着 42 的已兑现的 Promise。
        // / onRejected 返回 42，它被封装在已兑现的 Promise 中
        // Promise.reject().then(()=>console.log('success'),()=>console.log('failse')) // failse
        // let p3 = Promise.reject().then(()=>99,()=>42)
        // p3.then(res=>console.log(res),err=>console.log(err)) // 42
            

        // then返回值是promise
    //     const rejectFunc = (resolve,reject)=>{
    //         setTimeout(() => {
    //             reject(new Error('just error'))
    //         }, 1000);
    //     }
        
    //     const p4 = Promise.resolve('foo').then(()=>{
    //         return new Promise(rejectFunc)
    //     })
    //    p4.then(res=>console.log(res)).catch(err=>console.log(err)) // just error 

        // thend的异步
        const r1 = Promise.resolve(33)
        console.log(r1); // 1 {<fulfilled>: 33}
        const thenR1 = r1.then(val=>{
            console.log('val',val+1,'----'); //3  val 34 
            return val +1  
        })
        console.log(thenR1); // 2  {<pending>}
        setTimeout(() => { 
            console.log(thenR1); // 4 {<fulfilled>: 34}
        }, 1000);
    </script>
</body>
</html>